Workbook

Sheet Capacidade UAS-CUAS
A1: GRUPO DE INTERVENÇÃO DE ORDEM PÚBLICA — EFETIVO DA CAPACIDADE UAS / C-UAS
A2: Unidade de Intervenção / GNR · Documento de trabalho · Formação: ☑ possui / ☐ não possui
A3: Área funcional | B3: Subunidade | C3: Pelotão | D3: Posto | E3: NM | F3: Nome completo | G3: Apelido | H3: Contacto (TLM) | I3: CPRANT (Curso UAS) | J3: Curso C-UAS | K3: A1 | L3: A2 | M3: A3 | N3: N.º Certificado | O3: Validade | P3: Observações
A4: Coordenação | B4: Comando / SOI | C4: — | D4: Tenente | E4: 2140038 | F4: Luis Manuel Maceiro Cantante | G4: Cantante | H4: 935365179 | I4: ☐ | J4: ☑ | K4: ☑ | L4: ☐ | M4: ☑ | N4: LUX-RP-19960511top3 | O4: 46834
A5: Cmd / Sec | B5: Secretaria GIOP | C5: — | D5: Cabo | E5: 2020825 | F5: António João Carlos e Granja | G5: Granja | H5: 914286977 | I5: ☑ | J5: ☑ | K5: ☑ | L5: ☐ | M5: ☑ | N5: LUX-RP-19791213bqbv | O5: 47682
A6: Cmd / SOI | B6: SOI | C6: — | D6: Sarg. Ch | E6: 1970024 | F6: Manuel António Gonçalves Cordeiro | G6: Cordeiro | H6: 910086194 | I6: ☑ | J6: ☑ | K6: ☑ | L6: ☐ | M6: ☑ | N6: LUX-RP-19730205mwoj | O6: 46756 | P6: Deu-se como Voluntário 9 / 10 / 11
A7: Cmd / SOI | B7: SOI | C7: — | D7: 1º Sarg. | E7: 2031108 | F7: Hélder Simão Nunes | G7: Nunes | H7: 932780210 | I7: ☐ | J7: ☐ | K7: ☑ | L7: ☐ | M7: ☑ | N7: LUX-rp-19790416xwjw | O7: 25/08/2031
A8: Cmd / SOI | B8: SOI | C8: — | D8: Cabo Ch | E8: 2030883 | F8: Paulo Sérgio Pessanha Saraiva Loureiro | G8: Loureiro | H8: 965741001 | I8: ☐ | J8: ☐ | K8: ☑ | L8: ☐ | M8: ☑ | N8: LUX-RP-19781221snzn | O8: 46761
A9: Cmd / SOI | B9: SOI | C9: — | D9: Cabo Ch | E9: 2040618 | F9: Paulo Alexandre Nunes Fernandes Estêvão | G9: Estevão | H9: 962354196 | I9: ☑ | J9: ☑ | K9: ☑ | L9: ☐ | M9: ☑ | N9: LUX-RP-19790126wand | O9: 46737
A10: Cmd / SOI | B10: SOI | C10: — | D10: Cabo | E10: 2090487 | F10: Wilson da Silva Sousa | G10: Sousa | H10: 911057601 | I10: ☐ | J10: ☑ | K10: ☑ | L10: ☐ | M10: ☑ | N10: LUX-RP-19880811iww0 | O10: 46753 | P10: Deu-se como Voluntário 9 / 10 / 11
A11: Cmd / SOI | B11: SOI | C11: — | D11: Cabo | E11: 2030644 | F11: Bruno Miguel Correia Pimenta | G11: Pimenta | H11: 968351779 | I11: ☑ | J11: ☑ | K11: ☑ | L11: ☑ | M11: ☑ | N11: PRT-RP-3e2e110fc693 | O11: 47328
A12: Cmd / SOI | B12: SOI | C12: — | D12: Cabo | E12: 2030052 | F12: Filipe Jorge dos Santos Silva | G12: Silva | H12: 918192135 | I12: ☑ | J12: ☑ | K12: ☑ | L12: ☐ | M12: ☑ | N12: LUX-RP-19790708pyj7 | O12: 46754
A13: Cmd / SOI | B13: SOI | C13: — | D13: Cabo | E13: 2040185 | F13: Carlos Manuel Jorge dos Santos | G13: Santos | H13: 966228675 | I13: ☐ | J13: ☐ | K13: ☑ | L13: ☐ | M13: ☑ | N13: LUX-RP-19800517tyge | O13: 46788
A14: Cmd / SOI | B14: SOI | C14: — | D14: Cabo | E14: 2070317 | F14: José Carlos Soares Gomes | G14: Gomes | H14: 969747877 | I14: ☐ | J14: ☐ | K14: ☑ | L14: ☐ | M14: ☑ | N14: LUX-RP-19850627djem | O14: 47750
A15: Cmd / SOI | B15: SOI | C15: — | D15: Cabo | E15: 2050124 | F15: Jorge Manuel Marques Vitorino | G15: Vitorino | H15: 962991874 | I15: ☐ | J15: ☐ | K15: ☑ | L15: ☐ | M15: ☑ | N15: LUX-RP-19810702llnw | O15: 28-07-2027 | P15: Curso Tecnicop de MAnutenção de Drones
A16: Graduado — 1.ª Companhia | B16: 1.ª Companhia | C16: 1.º Pelotão | D16: Sarg. Aj | E16: 2000474 | F16: Jorge Manuel Graça Rodrigues | G16: Rodrigues | H16: 938807924 | I16: ☑ | J16: ☐ | K16: ☑ | L16: ☐ | M16: ☑ | N16: LUX-RP-19771222qqim | O16: 46783
A17: Operadores — 1.ª Companhia | B17: 1.ª Companhia | C17: 1.º Pelotão | D17: Cabo | E17: 1970349 | F17: Paulo Aurélio Fernandes Alves | G17: Alves | H17: 967001966 | I17: ☐ | J17: ☐ | K17: ☑ | L17: ☐ | M17: ☑ | N17: LUX-RP-19751010xsav | O17: 48046
A18: Operadores — 1.ª Companhia | B18: 1.ª Companhia | C18: 1.º Pelotão | D18: Cabo | E18: 2000796 | F18: Jorge António Monteiro Silvano | G18: Silvano | H18: 931117347 | I18: ☑ | J18: ☐ | K18: ☑ | L18: ☐ | M18: ☑ | N18: LUX-RP-19771101okaj | O18: 48023
A19: Operadores — 1.ª Companhia | B19: 1.ª Companhia | C19: 1.º Pelotão | D19: Cabo | E19: 2070254 | F19: Sílvio Manuel Supico Serra | G19: Serra | H19: 915568450 | I19: ☐ | J19: ☐ | K19: ☑ | L19: ☐ | M19: ☑ | N19: LUX-RP-19800124dmfu | O19: 48047
A20: Operadores — 1.ª Companhia | B20: 1.ª Companhia | C20: 1.º Pelotão | D20: Grd Pr | E20: 2150382 | F20: Pedro Miguel Rodrigues Carrapatoso | G20: Carrapatoso | H20: 912334272 | I20: ☐ | J20: ☐ | K20: ☑ | L20: ☐ | M20: ☑ | N20: LUX-RP-19881103rzss | O20: 48043
A21: Operadores — 1.ª Companhia | B21: 1.ª Companhia | C21: 1.º Pelotão | D21: Grd | E21: 2210742 | F21: Leandro Filipe da Cruz Silva | G21: Silva | H21: 916029284 | I21: ☐ | J21: ☐ | K21: ☑ | L21: ☐ | M21: ☑ | N21: LUX-RP-20010914wgwe | O21: 48047
A22: Graduado — 1.ª Companhia | B22: 1.ª Companhia | C22: 2.º Pelotão | D22: Sarg. Aj | E22: 2071127 | F22: Alexandre Dias Ramalheiro | G22: Ramalheiro | H22: 969341443 | I22: ☐ | J22: ☐ | K22: ☑ | L22: ☐ | M22: ☑ | N22: LUX-RP-19850705sohl | O22: 48056
A23: Operadores — 1.ª Companhia | B23: 1.ª Companhia | C23: 2.º Pelotão | D23: Cabo Ch | E23: 2000318 | F23: Rui Fernando Oliveira Custódio | G23: Custódio | H23: 926674323 | I23: ☐ | J23: ☐ | K23: ☑ | L23: ☐ | M23: ☑ | N23: LUX-RP-19760827exe5 | O23: 48042
A24: Operadores — 1.ª Companhia | B24: 1.ª Companhia | C24: 2.º Pelotão | D24: Cabo | E24: 2030636 | F24: Francisco João Alves Silvestre | G24: Silvestre | H24: 934475861 | I24: ☐ | J24: ☐ | K24: ☑ | L24: ☑ | M24: ☑ | N24: NLD-RP-9r4mdbrk1otl | O24: 47892
A25: Operadores — 1.ª Companhia | B25: 1.ª Companhia | C25: 2.º Pelotão | D25: Cabo | E25: 2040499 | F25: Daniel de Almeida Campos Dias | G25: Dias | H25: 963783179 | I25: ☑ | J25: ☐ | K25: ☑ | L25: ☐ | M25: ☑ | N25: LUX-RP-19820113vvyi | O25: 46754
A26: Operadores — 1.ª Companhia | B26: 1.ª Companhia | C26: 2.º Pelotão | D26: Cabo | E26: 2060731 | F26: André Simões Sabino | G26: Sabino | H26: 968137808 | I26: ☐ | J26: ☐ | K26: ☑ | L26: ☐ | M26: ☑ | N26: NLD-RP-wv64r1mtulu2 | O26: 47901
A27: Operadores — 1.ª Companhia | B27: 1.ª Companhia | C27: 2.º Pelotão | D27: Cabo | E27: 2071255 | F27: Marco Paulo Pedro Santos | G27: Santos | H27: 966722389 | I27: ☐ | J27: ☐ | K27: ☑ | L27: ☐ | M27: ☑ | N27: LUX-RP-19800528obz5 | O27: 47870
A28: Operadores — 1.ª Companhia | B28: 1.ª Companhia | C28: 2.º Pelotão | D28: Grd Pr | E28: 2100421 | F28: Jacinto Manuel Farinho Neves | G28: Neves | H28: 938311662 | I28: ☐ | J28: ☐ | K28: ☑ | L28: ☐ | M28: ☑ | N28: LUX-RP-19851026fcs1 | O28: 48042 | P28: Deu-se como Voluntário 9 / 10 / 11
A29: Operadores — 1.ª Companhia | B29: 1.ª Companhia | C29: 2.º Pelotão | D29: Grd Pr | E29: 2140080 | F29: Filipe Pimenta da Silva Rodrigues Vaquinhas Pereira de Melo | G29: Melo | H29: 919909638 | I29: ☐ | J29: ☐ | K29: ☑ | L29: ☐ | M29: ☑ | N29: LUX-RP-19891016lvgs | O29: 47887
A30: Graduado — 1.ª Companhia | B30: 1.ª Companhia | C30: 3.º Pelotão | D30: 1º Sarg. | E30: 2060327 | F30: Alfredo Rodrigues Moreira da Cunha | G30: Cunha | H30: 936962179 | I30: ☐ | J30: ☐ | K30: ☑ | L30: ☐ | M30: ☑ | N30: LUX-RP-19830402dae8 | O30: 47865
A31: Operadores — 1.ª Companhia | B31: 1.ª Companhia | C31: 3.º Pelotão | D31: Cabo | E31: 2040169 | F31: Carlos André Simão Vieira | G31: Vieira | H31: 964432379 | I31: ☐ | J31: ☐ | K31: ☑ | L31: ☐ | M31: ☑ | N31: LUX-RP-19811226mqu6 | O31: 46752
A32: Operadores — 1.ª Companhia | B32: 1.ª Companhia | C32: 3.º Pelotão | D32: Cabo | E32: 2040351 | F32: Nuno Gonçalo Moreira Rodrigues | G32: Rodrigues | H32: 925305752 | I32: ☐ | J32: ☐ | K32: ☑ | L32: ☐ | M32: ☑ | N32: LUX-RP-19820404bcri | O32: 46749
A33: Operadores — 1.ª Companhia | B33: 1.ª Companhia | C33: 3.º Pelotão | D33: Cabo | E33: 2090816 | F33: Nelson Ricardo Amorim da Costa | G33: Costa | H33: 933266501 | I33: ☐ | J33: ☐ | K33: ☑ | L33: ☐ | M33: ☑ | N33: LUX-RP-19820411llwf | O33: 48045
A34: Operadores — 1.ª Companhia | B34: 1.ª Companhia | C34: 3.º Pelotão | D34: Cabo | E34: 2020440 | F34: Rodrigo Alexandre Rosa Mateus Calado | G34: Calado | H34: 919500626 | I34: ☐ | J34: ☐ | K34: ☑ | L34: ☐ | M34: ☑ | N34: LUX-RP-19780816ixvy | O34: 46754
A35: Operadores — 1.ª Companhia | B35: 1.ª Companhia | C35: 3.º Pelotão | D35: Grd Pr | E35: 2160312 | F35: Pedro Miguel Martins Nunes | G35: Nunes | H35: 968101366 | I35: ☐ | J35: ☐ | K35: ☑ | L35: ☐ | M35: ☑ | N35: LUX-RP-19890503hwd8 | O35: 48051
A36: Operadores — 1.ª Companhia | B36: 1.ª Companhia | C36: 3.º Pelotão | D36: Grd | E36: 2180148 | F36: Rui Miguel Gonçalves Ribeiro | G36: Ribeiro | H36: 918859280 | I36: ☑ | J36: ☐ | K36: ☑ | L36: ☐ | M36: ☑ | N36: LUX-RP-19910918zdfh | O36: 46750 | P36: Deu-se como Voluntário 9 / 10 / 11
A37: Operadores — 1.ª Companhia | B37: 1.ª Companhia | C37: 3.º Pelotão | D37: Grd | E37: 2211307 | F37: João Pedro da Silva Soares | G37: Soares | H37: 913178281 | I37: ☐ | J37: ☐ | K37: ☑ | L37: ☐ | M37: ☑ | N37: LUX-RP-20001119qxde | O37: 48046
A38: Operadores — 2.ª Companhia | B38: 2.ª Companhia | C38: 4.º Pelotão | D38: Cabo Ch | E38: 1990953 | F38: Orlando Augusto Gil Cosme | G38: Cosme | H38: 966146592 | I38: ☐ | J38: ☐ | K38: ☑ | L38: ☐ | M38: ☑ | N38: LUX-RP-19770711epuo | O38: 46745 | P38: Deu-se como Voluntário 9 / 10 / 11
A39: Operadores — 2.ª Companhia | B39: 2.ª Companhia | C39: 4.º Pelotão | D39: Cabo | E39: 2060540 | F39: Alexandre Filipe Correia Tomázio | G39: Tomázio | I39: ☐ | J39: ☐ | K39: ☑ | L39: ☐ | M39: ☑ | P39: Reprovou 1x nos testes
A40: Operadores — 2.ª Companhia | B40: 2.ª Companhia | C40: 4.º Pelotão | D40: Grd Pr | E40: 2150076 | F40: Dany David Ferreira Domingues | G40: Domingues | H40: 919194098 | I40: ☐ | J40: ☐ | K40: ☐ | L40: ☐ | M40: ☐
...

Sheet Análise
A1: ANÁLISE DO EFETIVO DA CAPACIDADE UAS / C-UAS
A3: Efetivo por origem (subunidade) | D3: Efetivo por posto | G3: Estrutura de comando
A4: Origem | B4: Efetivo | D4: Posto | E4: Efetivo | G4: Escalão | H4: N.º
A5: Comando / SOI | B5: =COUNTIF('Capacidade UAS-CUAS'!$B$4:$B$81,"Comando / SOI")+COUNTIF('Capacidade UAS-CUAS'!$B$4:$B$81,"Secretaria GIOP")+COUNTIF('Capacidade UAS-CUAS'!$B$4:$B$81,"SOI") -> 12 | D5: Tenente | E5: =COUNTIF('Capacidade UAS-CUAS'!$D$4:$D$81,"Tenente") -> 1 | G5: Coordenador | H5: =COUNTIF('Capacidade UAS-CUAS'!$A$4:$A$81,"Coordenação") -> 1
A6: 1.ª Companhia | B6: =COUNTIF('Capacidade UAS-CUAS'!$B$4:$B$81,"1.ª Companhia") -> 22 | D6: Sarg. Ch | E6: =COUNTIF('Capacidade UAS-CUAS'!$D$4:$D$81,"Sarg. Ch") -> 1 | G6: Graduados (Sargentos) | H6: =COUNTIF('Capacidade UAS-CUAS'!$D$4:$D$81,"Sarg. Ch")+COUNTIF('Capacidade UAS-CUAS'!$D$4:$D$81,"Sarg. Aj")+COUNTIF('Capacidade UAS-CUAS'!$D$4:$D$81,"1º Sarg.")+COUNTIF('Capacidade UAS-CUAS'!$D$4:$D$81,"2º Sarg.") -> 11
A7: 2.ª Companhia | B7: =COUNTIF('Capacidade UAS-CUAS'!$B$4:$B$81,"2.ª Companhia") -> 18 | D7: Sarg. Aj | E7: =COUNTIF('Capacidade UAS-CUAS'!$D$4:$D$81,"Sarg. Aj") -> 2 | G7: Restantes elementos | H7: =COUNTA('Capacidade UAS-CUAS'!$D$4:$D$81)-H5-H6 -> 66
A8: 3.ª Companhia | B8: =COUNTIF('Capacidade UAS-CUAS'!$B$4:$B$81,"3.ª Companhia") -> 20 | D8: 1º Sarg. | E8: =COUNTIF('Capacidade UAS-CUAS'!$D$4:$D$81,"1º Sarg.") -> 6
A9: 4.ª Companhia | B9: =COUNTIF('Capacidade UAS-CUAS'!$B$4:$B$81,"4.ª Companhia") -> 6 | D9: 2º Sarg. | E9: =COUNTIF('Capacidade UAS-CUAS'!$D$4:$D$81,"2º Sarg.") -> 2
A10: TOTAL | B10: =SUM(B5:B9) -> 78 | D10: Cabo Mor | E10: =COUNTIF('Capacidade UAS-CUAS'!$D$4:$D$81,"Cabo Mor") -> 1
D11: Cabo Ch | E11: =COUNTIF('Capacidade UAS-CUAS'!$D$4:$D$81,"Cabo Ch") -> 5
D12: Cabo | E12: =COUNTIF('Capacidade UAS-CUAS'!$D$4:$D$81,"Cabo") -> 36
D13: Grd Pr | E13: =COUNTIF('Capacidade UAS-CUAS'!$D$4:$D$81,"Grd Pr") -> 15
D14: Grd | E14: =COUNTIF('Capacidade UAS-CUAS'!$D$4:$D$81,"Grd") -> 9
D15: TOTAL | E15: =SUM(E5:E14) -> 78
A18: Cobertura formativa (n.º de militares com o curso)
A19: Formação | B19: Com curso (☑) | C19: % do efetivo
A20: CPRANT (Curso UAS) | B20: =COUNTIF('Capacidade UAS-CUAS'!$I$4:$I$81,"☑") -> 12 | C20: =B20/COUNTA('Capacidade UAS-CUAS'!$E$4:$E$81) -> 0.15384615
A21: Curso C-UAS | B21: =COUNTIF('Capacidade UAS-CUAS'!$J$4:$J$81,"☑") -> 7 | C21: =B21/COUNTA('Capacidade UAS-CUAS'!$E$4:$E$81) -> 0.08974359
A22: A1 | B22: =COUNTIF('Capacidade UAS-CUAS'!$K$4:$K$81,"☑") -> 74 | C22: =B22/COUNTA('Capacidade UAS-CUAS'!$E$4:$E$81) -> 0.94871795
A23: A2 | B23: =COUNTIF('Capacidade UAS-CUAS'!$L$4:$L$81,"☑") -> 2 | C23: =B23/COUNTA('Capacidade UAS-CUAS'!$E$4:$E$81) -> 0.025641026
A24: A3 | B24: =COUNTIF('Capacidade UAS-CUAS'!$M$4:$M$81,"☑") -> 74 | C24: =B24/COUNTA('Capacidade UAS-CUAS'!$E$4:$E$81) -> 0.94871795
F38: RELAÇÃO DE GRADUADOS (SARGENTOS)
F39: # | G39: Posto | H39: NM | I39: Nome | J39: Subunidade | K39: Antiguidade
F40: 1 | G40: Sarg. Ch | H40: 1970024 | I40: Manuel António Gonçalves Cordeiro | J40: SOI | K40: 268
F41: 2 | G41: Sarg. Aj | H41: 2000474 | I41: Jorge Manuel Graça Rodrigues | J41: 1.ª Companhia | K41: 1337
F42: 3 | G42: Sarg. Aj | H42: 2071127 | I42: Alexandre Dias Ramalheiro | J42: 1.ª Companhia | K42: 1546
F43: 4 | G43: 1º Sarg. | H43: 2031108 | I43: Hélder Simão Nunes | J43: SOI | K43: 1627
F44: 5 | G44: 1º Sarg. | H44: 2060327 | I44: Alfredo Rodrigues Moreira da Cunha | J44: 1.ª Companhia | K44: 1657
F45: 6 | G45: 1º Sarg. | H45: 2100420 | I45: Rúben Alexandre Avelino Valente | J45: 3.ª Companhia | K45: 1899
F46: 7 | G46: 1º Sarg. | H46: 2150448 | I46: João Maria Domingos Henriques | J46: 2.ª Companhia | K46: 1906
F47: 8 | G47: 1º Sarg. | H47: 2140147 | I47: Fábio Emanuel Morgado Gomes | J47: 3.ª Companhia | K47: 1908
F48: 9 | G48: 1º Sarg. | H48: 2090305 | I48: Fabio Emanuel Marques Antunes | J48: 2.ª Companhia | K48: 1984
F49: 10 | G49: 2º Sarg. | H49: 2160072 | I49: Eduardo Luis Nogueira Barbosa | J49: 4.ª Companhia | K49: 2027
F50: 11 | G50: 2º Sarg. | H50: 2140655 | I50: Bruno Alexandre Marques Ferreira | J50: 3.ª Companhia | K50: 2098
F51: Total de graduados: | I51: 11

Sheet Serviços
A1: GRUPO DE INTERVENÇÃO DE ORDEM PÚBLICA — REGISTO DE SERVIÇOS UAS / C-UAS
A2: Nome, Subunidade e Posto preenchem automaticamente a partir do NM
A3: Data | B3: NM | C3: Nome | D3: Subunidade | E3: Posto | F3: Tipo de Serviço | G3: UAS USADO | H3: Categoria | I3: N.º NOTAM | J3: Local | K3: Observações
A4: 46198 | B4: 2040618 | C4: =IFERROR(INDEX('Capacidade UAS-CUAS'!$F$4:$F$81,MATCH($B4,'Capacidade UAS-CUAS'!$E$4:$E$81,0)),"") -> Paulo Alexandre Nunes Fernandes Estêvão | D4: =IFERROR(INDEX('Capacidade UAS-CUAS'!$B$4:$B$81,MATCH($B4,'Capacidade UAS-CUAS'!$E$4:$E$81,0)),"") -> SOI | E4: =IFERROR(INDEX('Capacidade UAS-CUAS'!$D$4:$D$81,MATCH($B4,'Capacidade UAS-CUAS'!$E$4:$E$81,0)),"") -> Cabo Ch | F4: C-UAS | H4: Exercício | J4: Tomar | K4: Cirex - Curso de Infraestruturas
A5: 46198 | B5: 2090487 | C5: =IFERROR(INDEX('Capacidade UAS-CUAS'!$F$4:$F$81,MATCH($B5,'Capacidade UAS-CUAS'!$E$4:$E$81,0)),"") -> Wilson da Silva Sousa | D5: =IFERROR(INDEX('Capacidade UAS-CUAS'!$B$4:$B$81,MATCH($B5,'Capacidade UAS-CUAS'!$E$4:$E$81,0)),"") -> SOI | E5: =IFERROR(INDEX('Capacidade UAS-CUAS'!$D$4:$D$81,MATCH($B5,'Capacidade UAS-CUAS'!$E$4:$E$81,0)),"") -> Cabo | F5: C-UAS | H5: Exercício | J5: Tomar | K5: Cirex - Curso de Infraestruturas
A6: 46198 | B6: 2040351 | C6: =IFERROR(INDEX('Capacidade UAS-CUAS'!$F$4:$F$81,MATCH($B6,'Capacidade UAS-CUAS'!$E$4:$E$81,0)),"") -> Nuno Gonçalo Moreira Rodrigues | D6: =IFERROR(INDEX('Capacidade UAS-CUAS'!$B$4:$B$81,MATCH($B6,'Capacidade UAS-CUAS'!$E$4:$E$81,0)),"") -> 1.ª Companhia | E6: =IFERROR(INDEX('Capacidade UAS-CUAS'!$D$4:$D$81,MATCH($B6,'Capacidade UAS-CUAS'!$E$4:$E$81,0)),"") -> Cabo | F6: C-UAS | H6: Exercício | J6: Tomar | K6: Cirex - Curso de Infraestruturas
A7: 46198 | B7: 2180148 | C7: =IFERROR(INDEX('Capacidade UAS-CUAS'!$F$4:$F$81,MATCH($B7,'Capacidade UAS-CUAS'!$E$4:$E$81,0)),"") -> Rui Miguel Gonçalves Ribeiro | D7: =IFERROR(INDEX('Capacidade UAS-CUAS'!$B$4:$B$81,MATCH($B7,'Capacidade UAS-CUAS'!$E$4:$E$81,0)),"") -> 1.ª Companhia | E7: =IFERROR(INDEX('Capacidade UAS-CUAS'!$D$4:$D$81,MATCH($B7,'Capacidade UAS-CUAS'!$E$4:$E$81,0)),"") -> Grd | F7: C-UAS | H7: Exercício | J7: Tomar | K7: Cirex - Curso de Infraestruturas
A8: 46204 | B8: 2040618 | C8: =IFERROR(INDEX('Capacidade UAS-CUAS'!$F$4:$F$81,MATCH($B8,'Capacidade UAS-CUAS'!$E$4:$E$81,0)),"") -> Paulo Alexandre Nunes Fernandes Estêvão | D8: =IFERROR(INDEX('Capacidade UAS-CUAS'!$B$4:$B$81,MATCH($B8,'Capacidade UAS-CUAS'!$E$4:$E$81,0)),"") -> SOI | E8: =IFERROR(INDEX('Capacidade UAS-CUAS'!$D$4:$D$81,MATCH($B8,'Capacidade UAS-CUAS'!$E$4:$E$81,0)),"") -> Cabo Ch | F8: UAS | G8: 3T | H8: Recolha de Imagens | I8: Notam Pedido | J8: Albufeira
A9: 46204 | B9: 2070317 | C9: =IFERROR(INDEX('Capacidade UAS-CUAS'!$F$4:$F$81,MATCH($B9,'Capacidade UAS-CUAS'!$E$4:$E$81,0)),"") -> José Carlos Soares Gomes | D9: =IFERROR(INDEX('Capacidade UAS-CUAS'!$B$4:$B$81,MATCH($B9,'Capacidade UAS-CUAS'!$E$4:$E$81,0)),"") -> SOI | E9: =IFERROR(INDEX('Capacidade UAS-CUAS'!$D$4:$D$81,MATCH($B9,'Capacidade UAS-CUAS'!$E$4:$E$81,0)),"") -> Cabo | F9: UAS | G9: 3T | H9: Recolha de Imagens | I9: Notam Pedido | J9: Albufeira
A10: 46206 | B10: 2040618 | C10: =IFERROR(INDEX('Capacidade UAS-CUAS'!$F$4:$F$81,MATCH($B10,'Capacidade UAS-CUAS'!$E$4:$E$81,0)),"") -> Paulo Alexandre Nunes Fernandes Estêvão | D10: =IFERROR(INDEX('Capacidade UAS-CUAS'!$B$4:$B$81,MATCH($B10,'Capacidade UAS-CUAS'!$E$4:$E$81,0)),"") -> SOI | E10: =IFERROR(INDEX('Capacidade UAS-CUAS'!$D$4:$D$81,MATCH($B10,'Capacidade UAS-CUAS'!$E$4:$E$81,0)),"") -> Cabo Ch | F10: UAS | G10: 3T Mini3 Pro | H10: Exercício | J10: Santa Margarida | K10: Exercicio Leão
A11: 46206 | B11: 1970024 | C11: =IFERROR(INDEX('Capacidade UAS-CUAS'!$F$4:$F$81,MATCH($B11,'Capacidade UAS-CUAS'!$E$4:$E$81,0)),"") -> Manuel António Gonçalves Cordeiro | D11: =IFERROR(INDEX('Capacidade UAS-CUAS'!$B$4:$B$81,MATCH($B11,'Capacidade UAS-CUAS'!$E$4:$E$81,0)),"") -> SOI | E11: =IFERROR(INDEX('Capacidade UAS-CUAS'!$D$4:$D$81,MATCH($B11,'Capacidade UAS-CUAS'!$E$4:$E$81,0)),"") -> Sarg. Ch | F11: UAS | G11: 3T Mini3 Pro | H11: Exercício | J11: Santa Margarida | K11: Exercicio Leão
A12: 46206 | B12: 2090487 | C12: =IFERROR(INDEX('Capacidade UAS-CUAS'!$F$4:$F$81,MATCH($B12,'Capacidade UAS-CUAS'!$E$4:$E$81,0)),"") -> Wilson da Silva Sousa | D12: =IFERROR(INDEX('Capacidade UAS-CUAS'!$B$4:$B$81,MATCH($B12,'Capacidade UAS-CUAS'!$E$4:$E$81,0)),"") -> SOI | E12: =IFERROR(INDEX('Capacidade UAS-CUAS'!$D$4:$D$81,MATCH($B12,'Capacidade UAS-CUAS'!$E$4:$E$81,0)),"") -> Cabo | F12: UAS | G12: 3T Mini3 Pro | H12: Exercício | J12: Santa Margarida | K12: Exercicio Leão
A13: 46206 | B13: 2040618 | C13: =IFERROR(INDEX('Capacidade UAS-CUAS'!$F$4:$F$81,MATCH($B13,'Capacidade UAS-CUAS'!$E$4:$E$81,0)),"") -> Paulo Alexandre Nunes Fernandes Estêvão | D13: =IFERROR(INDEX('Capacidade UAS-CUAS'!$B$4:$B$81,MATCH($B13,'Capacidade UAS-CUAS'!$E$4:$E$81,0)),"") -> SOI | E13: =IFERROR(INDEX('Capacidade UAS-CUAS'!$D$4:$D$81,MATCH($B13,'Capacidade UAS-CUAS'!$E$4:$E$81,0)),"") -> Cabo Ch | F13: C-UAS | H13: Exercício | J13: Santa Margarida | K13: Exercicio Leão
A14: 46206 | B14: 1970024 | C14: =IFERROR(INDEX('Capacidade UAS-CUAS'!$F$4:$F$81,MATCH($B14,'Capacidade UAS-CUAS'!$E$4:$E$81,0)),"") -> Manuel António Gonçalves Cordeiro | D14: =IFERROR(INDEX('Capacidade UAS-CUAS'!$B$4:$B$81,MATCH($B14,'Capacidade UAS-CUAS'!$E$4:$E$81,0)),"") -> SOI | E14: =IFERROR(INDEX('Capacidade UAS-CUAS'!$D$4:$D$81,MATCH($B14,'Capacidade UAS-CUAS'!$E$4:$E$81,0)),"") -> Sarg. Ch | F14: C-UAS | H14: Exercício | J14: Santa Margarida | K14: Exercicio Leão
A15: 46206 | B15: 2090487 | C15: =IFERROR(INDEX('Capacidade UAS-CUAS'!$F$4:$F$81,MATCH($B15,'Capacidade UAS-CUAS'!$E$4:$E$81,0)),"") -> Wilson da Silva Sousa | D15: =IFERROR(INDEX('Capacidade UAS-CUAS'!$B$4:$B$81,MATCH($B15,'Capacidade UAS-CUAS'!$E$4:$E$81,0)),"") -> SOI | E15: =IFERROR(INDEX('Capacidade UAS-CUAS'!$D$4:$D$81,MATCH($B15,'Capacidade UAS-CUAS'!$E$4:$E$81,0)),"") -> Cabo | F15: C-UAS | H15: Exercício | J15: Santa Margarida | K15: Exercicio Leão
A16: 46237 | B16: 2040618 | C16: =IFERROR(INDEX('Capacidade UAS-CUAS'!$F$4:$F$81,MATCH($B16,'Capacidade UAS-CUAS'!$E$4:$E$81,0)),"") -> Paulo Alexandre Nunes Fernandes Estêvão | D16: =IFERROR(INDEX('Capacidade UAS-CUAS'!$B$4:$B$81,MATCH($B16,'Capacidade UAS-CUAS'!$E$4:$E$81,0)),"") -> SOI | E16: =IFERROR(INDEX('Capacidade UAS-CUAS'!$D$4:$D$81,MATCH($B16,'Capacidade UAS-CUAS'!$E$4:$E$81,0)),"") -> Cabo Ch | F16: UAS | G16: 3T | H16: Reconhecimento | I16: Notam Pedido | J16: Coruche
A17: 46237 | B17: 2030055 | C17: =IFERROR(INDEX('Capacidade UAS-CUAS'!$F$4:$F$81,MATCH($B17,'Capacidade UAS-CUAS'!$E$4:$E$81,0)),"") -> Victor Emanuel Cortinhas de Sousa Rosa | D17: =IFERROR(INDEX('Capacidade UAS-CUAS'!$B$4:$B$81,MATCH($B17,'Capacidade UAS-CUAS'!$E$4:$E$81,0)),"") -> 3.ª Companhia | E17: =IFERROR(INDEX('Capacidade UAS-CUAS'!$D$4:$D$81,MATCH($B17,'Capacidade UAS-CUAS'!$E$4:$E$81,0)),"") -> Cabo | F17: UAS | G17: 3T | H17: Reconhecimento | I17: Notam Pedido | J17: Coruche
A18: 46242 | B18: 2040618 | C18: =IFERROR(INDEX('Capacidade UAS-CUAS'!$F$4:$F$81,MATCH($B18,'Capacidade UAS-CUAS'!$E$4:$E$81,0)),"") -> Paulo Alexandre Nunes Fernandes Estêvão | D18: =IFERROR(INDEX('Capacidade UAS-CUAS'!$B$4:$B$81,MATCH($B18,'Capacidade UAS-CUAS'!$E$4:$E$81,0)),"") -> SOI | E18: =IFERROR(INDEX('Capacidade UAS-CUAS'!$D$4:$D$81,MATCH($B18,'Capacidade UAS-CUAS'!$E$4:$E$81,0)),"") -> Cabo Ch | F18: UAS | G18: 3T | H18: Recolha de Imagens | I18: Notam Pedido | J18: Campo Maior
A19: 46242 | B19: 2030883 | C19: =IFERROR(INDEX('Capacidade UAS-CUAS'!$F$4:$F$81,MATCH($B19,'Capacidade UAS-CUAS'!$E$4:$E$81,0)),"") -> Paulo Sérgio Pessanha Saraiva Loureiro | D19: =IFERROR(INDEX('Capacidade UAS-CUAS'!$B$4:$B$81,MATCH($B19,'Capacidade UAS-CUAS'!$E$4:$E$81,0)),"") -> SOI | E19: =IFERROR(INDEX('Capacidade UAS-CUAS'!$D$4:$D$81,MATCH($B19,'Capacidade UAS-CUAS'!$E$4:$E$81,0)),"") -> Cabo Ch | F19: UAS | G19: 3T | H19: Recolha de Imagens | I19: Notam Pedido | J19: Campo Maior
A20: 13/08/2026 | B20: 2030883 | C20: =IFERROR(INDEX('Capacidade UAS-CUAS'!$F$4:$F$81,MATCH($B20,'Capacidade UAS-CUAS'!$E$4:$E$81,0)),"") -> Paulo Sérgio Pessanha Saraiva Loureiro | D20: =IFERROR(INDEX('Capacidade UAS-CUAS'!$B$4:$B$81,MATCH($B20,'Capacidade UAS-CUAS'!$E$4:$E$81,0)),"") -> SOI | E20: =IFERROR(INDEX('Capacidade UAS-CUAS'!$D$4:$D$81,MATCH($B20,'Capacidade UAS-CUAS'!$E$4:$E$81,0)),"") -> Cabo Ch | F20: C-UAS | G20: Mini3 Pro | H20: Apoio a Operação | J20: Fátima
A21: 13/08/2026 | B21: 2070317 | C21: =IFERROR(INDEX('Capacidade UAS-CUAS'!$F$4:$F$81,MATCH($B21,'Capacidade UAS-CUAS'!$E$4:$E$81,0)),"") -> José Carlos Soares Gomes | D21: =IFERROR(INDEX('Capacidade UAS-CUAS'!$B$4:$B$81,MATCH($B21,'Capacidade UAS-CUAS'!$E$4:$E$81,0)),"") -> SOI | E21: =IFERROR(INDEX('Capacidade UAS-CUAS'!$D$4:$D$81,MATCH($B21,'Capacidade UAS-CUAS'!$E$4:$E$81,0)),"") -> Cabo | F21: C-UAS | G21: Mini3 Pro | H21: Apoio a Operação | J21: Fátima
A22: 15/08/2023 | B22: 2040618 | C22: =IFERROR(INDEX('Capacidade UAS-CUAS'!$F$4:$F$81,MATCH($B22,'Capacidade UAS-CUAS'!$E$4:$E$81,0)),"") -> Paulo Alexandre Nunes Fernandes Estêvão | D22: =IFERROR(INDEX('Capacidade UAS-CUAS'!$B$4:$B$81,MATCH($B22,'Capacidade UAS-CUAS'!$E$4:$E$81,0)),"") -> SOI | E22: =IFERROR(INDEX('Capacidade UAS-CUAS'!$D$4:$D$81,MATCH($B22,'Capacidade UAS-CUAS'!$E$4:$E$81,0)),"") -> Cabo Ch | F22: C-UAS | G22: Mini3 Pro | H22: Apoio a Operação | J22: Fátima
A23: 46249 | B23: 2020825 | C23: =IFERROR(INDEX('Capacidade UAS-CUAS'!$F$4:$F$81,MATCH($B23,'Capacidade UAS-CUAS'!$E$4:$E$81,0)),"") -> António João Carlos e Granja | D23: =IFERROR(INDEX('Capacidade UAS-CUAS'!$B$4:$B$81,MATCH($B23,'Capacidade UAS-CUAS'!$E$4:$E$81,0)),"") -> Secretaria GIOP | E23: =IFERROR(INDEX('Capacidade UAS-CUAS'!$D$4:$D$81,MATCH($B23,'Capacidade UAS-CUAS'!$E$4:$E$81,0)),"") -> Cabo | F23: C-UAS | G23: Mini3 Pro | H23: Apoio a Operação | J23: Fátima
A24: 18/08/2026 | B24: 2040618 | C24: =IFERROR(INDEX('Capacidade UAS-CUAS'!$F$4:$F$81,MATCH($B24,'Capacidade UAS-CUAS'!$E$4:$E$81,0)),"") -> Paulo Alexandre Nunes Fernandes Estêvão | D24: =IFERROR(INDEX('Capacidade UAS-CUAS'!$B$4:$B$81,MATCH($B24,'Capacidade UAS-CUAS'!$E$4:$E$81,0)),"") -> SOI | E24: =IFERROR(INDEX('Capacidade UAS-CUAS'!$D$4:$D$81,MATCH($B24,'Capacidade UAS-CUAS'!$E$4:$E$81,0)),"") -> Cabo Ch | F24: UAS | G24: 3T | H24: Recolha de Imagens | I24: Notam Pedido | J24: Rio Maior
A25: 18/08/2026 | B25: 2020825 | C25: =IFERROR(INDEX('Capacidade UAS-CUAS'!$F$4:$F$81,MATCH($B25,'Capacidade UAS-CUAS'!$E$4:$E$81,0)),"") -> António João Carlos e Granja | D25: =IFERROR(INDEX('Capacidade UAS-CUAS'!$B$4:$B$81,MATCH($B25,'Capacidade UAS-CUAS'!$E$4:$E$81,0)),"") -> Secretaria GIOP | E25: =IFERROR(INDEX('Capacidade UAS-CUAS'!$D$4:$D$81,MATCH($B25,'Capacidade UAS-CUAS'!$E$4:$E$81,0)),"") -> Cabo | F25: UAS | G25: 3T | H25: Recolha de Imagens | I25: Notam Pedido | J25: Rio Maior
A26: 25/08/2026 | B26: 2030052 | C26: =IFERROR(INDEX('Capacidade UAS-CUAS'!$F$4:$F$81,MATCH($B26,'Capacidade UAS-CUAS'!$E$4:$E$81,0)),"") -> Filipe Jorge dos Santos Silva | D26: =IFERROR(INDEX('Capacidade UAS-CUAS'!$B$4:$B$81,MATCH($B26,'Capacidade UAS-CUAS'!$E$4:$E$81,0)),"") -> SOI | E26: =IFERROR(INDEX('Capacidade UAS-CUAS'!$D$4:$D$81,MATCH($B26,'Capacidade UAS-CUAS'!$E$4:$E$81,0)),"") -> Cabo | F26: UAS | G26: 3T | H26: Reconhecimento | I26: Notam Pedido | J26: Leiria
A27: 25/08/2026 | B27: 2070922 | C27: =IFERROR(INDEX('Capacidade UAS-CUAS'!$F$4:$F$81,MATCH($B27,'Capacidade UAS-CUAS'!$E$4:$E$81,0)),"") -> Nuno Pedro Rolo Correia Veloso | D27: =IFERROR(INDEX('Capacidade UAS-CUAS'!$B$4:$B$81,MATCH($B27,'Capacidade UAS-CUAS'!$E$4:$E$81,0)),"") -> 2.ª Companhia | E27: =IFERROR(INDEX('Capacidade UAS-CUAS'!$D$4:$D$81,MATCH($B27,'Capacidade UAS-CUAS'!$E$4:$E$81,0)),"") -> Cabo | F27: UAS | G27: 3T | H27: Reconhecimento | I27: Notam Pedido | J27: Leiria
A28: 46266 | B28: 2030052 | C28: =IFERROR(INDEX('Capacidade UAS-CUAS'!$F$4:$F$81,MATCH($B28,'Capacidade UAS-CUAS'!$E$4:$E$81,0)),"") -> Filipe Jorge dos Santos Silva | D28: =IFERROR(INDEX('Capacidade UAS-CUAS'!$B$4:$B$81,MATCH($B28,'Capacidade UAS-CUAS'!$E$4:$E$81,0)),"") -> SOI | E28: =IFERROR(INDEX('Capacidade UAS-CUAS'!$D$4:$D$81,MATCH($B28,'Capacidade UAS-CUAS'!$E$4:$E$81,0)),"") -> Cabo | F28: UAS | G28: 3T | H28: Reconhecimento | I28: Notam Pedido
A29: 46266 | B29: 2000796 | C29: =IFERROR(INDEX('Capacidade UAS-CUAS'!$F$4:$F$81,MATCH($B29,'Capacidade UAS-CUAS'!$E$4:$E$81,0)),"") -> Jorge António Monteiro Silvano | D29: =IFERROR(INDEX('Capacidade UAS-CUAS'!$B$4:$B$81,MATCH($B29,'Capacidade UAS-CUAS'!$E$4:$E$81,0)),"") -> 1.ª Companhia | E29: =IFERROR(INDEX('Capacidade UAS-CUAS'!$D$4:$D$81,MATCH($B29,'Capacidade UAS-CUAS'!$E$4:$E$81,0)),"") -> Cabo | F29: UAS | G29: 3T | H29: Reconhecimento | I29: Notam Pedido
C30: =IFERROR(INDEX('Capacidade UAS-CUAS'!$F$4:$F$81,MATCH($B30,'Capacidade UAS-CUAS'!$E$4:$E$81,0)),"") | D30: =IFERROR(INDEX('Capacidade UAS-CUAS'!$B$4:$B$81,MATCH($B30,'Capacidade UAS-CUAS'!$E$4:$E$81,0)),"") | E30: =IFERROR(INDEX('Capacidade UAS-CUAS'!$D$4:$D$81,MATCH($B30,'Capacidade UAS-CUAS'!$E$4:$E$81,0)),"")
C31: =IFERROR(INDEX('Capacidade UAS-CUAS'!$F$4:$F$81,MATCH($B31,'Capacidade UAS-CUAS'!$E$4:$E$81,0)),"") | D31: =IFERROR(INDEX('Capacidade UAS-CUAS'!$B$4:$B$81,MATCH($B31,'Capacidade UAS-CUAS'!$E$4:$E$81,0)),"") | E31: =IFERROR(INDEX('Capacidade UAS-CUAS'!$D$4:$D$81,MATCH($B31,'Capacidade UAS-CUAS'!$E$4:$E$81,0)),"")
C32: =IFERROR(INDEX('Capacidade UAS-CUAS'!$F$4:$F$81,MATCH($B32,'Capacidade UAS-CUAS'!$E$4:$E$81,0)),"") | D32: =IFERROR(INDEX('Capacidade UAS-CUAS'!$B$4:$B$81,MATCH($B32,'Capacidade UAS-CUAS'!$E$4:$E$81,0)),"") | E32: =IFERROR(INDEX('Capacidade UAS-CUAS'!$D$4:$D$81,MATCH($B32,'Capacidade UAS-CUAS'!$E$4:$E$81,0)),"")
C33: =IFERROR(INDEX('Capacidade UAS-CUAS'!$F$4:$F$81,MATCH($B33,'Capacidade UAS-CUAS'!$E$4:$E$81,0)),"") | D33: =IFERROR(INDEX('Capacidade UAS-CUAS'!$B$4:$B$81,MATCH($B33,'Capacidade UAS-CUAS'!$E$4:$E$81,0)),"") | E33: =IFERROR(INDEX('Capacidade UAS-CUAS'!$D$4:$D$81,MATCH($B33,'Capacidade UAS-CUAS'!$E$4:$E$81,0)),"")
C34: =IFERROR(INDEX('Capacidade UAS-CUAS'!$F$4:$F$81,MATCH($B34,'Capacidade UAS-CUAS'!$E$4:$E$81,0)),"") | D34: =IFERROR(INDEX('Capacidade UAS-CUAS'!$B$4:$B$81,MATCH($B34,'Capacidade UAS-CUAS'!$E$4:$E$81,0)),"") | E34: =IFERROR(INDEX('Capacidade UAS-CUAS'!$D$4:$D$81,MATCH($B34,'Capacidade UAS-CUAS'!$E$4:$E$81,0)),"")
C35: =IFERROR(INDEX('Capacidade UAS-CUAS'!$F$4:$F$81,MATCH($B35,'Capacidade UAS-CUAS'!$E$4:$E$81,0)),"") | D35: =IFERROR(INDEX('Capacidade UAS-CUAS'!$B$4:$B$81,MATCH($B35,'Capacidade UAS-CUAS'!$E$4:$E$81,0)),"") | E35: =IFERROR(INDEX('Capacidade UAS-CUAS'!$D$4:$D$81,MATCH($B35,'Capacidade UAS-CUAS'!$E$4:$E$81,0)),"")
C36: =IFERROR(INDEX('Capacidade UAS-CUAS'!$F$4:$F$81,MATCH($B36,'Capacidade UAS-CUAS'!$E$4:$E$81,0)),"") | D36: =IFERROR(INDEX('Capacidade UAS-CUAS'!$B$4:$B$81,MATCH($B36,'Capacidade UAS-CUAS'!$E$4:$E$81,0)),"") | E36: =IFERROR(INDEX('Capacidade UAS-CUAS'!$D$4:$D$81,MATCH($B36,'Capacidade UAS-CUAS'!$E$4:$E$81,0)),"")
C37: =IFERROR(INDEX('Capacidade UAS-CUAS'!$F$4:$F$81,MATCH($B37,'Capacidade UAS-CUAS'!$E$4:$E$81,0)),"") | D37: =IFERROR(INDEX('Capacidade UAS-CUAS'!$B$4:$B$81,MATCH($B37,'Capacidade UAS-CUAS'!$E$4:$E$81,0)),"") | E37: =IFERROR(INDEX('Capacidade UAS-CUAS'!$D$4:$D$81,MATCH($B37,'Capacidade UAS-CUAS'!$E$4:$E$81,0)),"")
C38: =IFERROR(INDEX('Capacidade UAS-CUAS'!$F$4:$F$81,MATCH($B38,'Capacidade UAS-CUAS'!$E$4:$E$81,0)),"") | D38: =IFERROR(INDEX('Capacidade UAS-CUAS'!$B$4:$B$81,MATCH($B38,'Capacidade UAS-CUAS'!$E$4:$E$81,0)),"") | E38: =IFERROR(INDEX('Capacidade UAS-CUAS'!$D$4:$D$81,MATCH($B38,'Capacidade UAS-CUAS'!$E$4:$E$81,0)),"")
C39: =IFERROR(INDEX('Capacidade UAS-CUAS'!$F$4:$F$81,MATCH($B39,'Capacidade UAS-CUAS'!$E$4:$E$81,0)),"") | D39: =IFERROR(INDEX('Capacidade UAS-CUAS'!$B$4:$B$81,MATCH($B39,'Capacidade UAS-CUAS'!$E$4:$E$81,0)),"") | E39: =IFERROR(INDEX('Capacidade UAS-CUAS'!$D$4:$D$81,MATCH($B39,'Capacidade UAS-CUAS'!$E$4:$E$81,0)),"")
C40: =IFERROR(INDEX('Capacidade UAS-CUAS'!$F$4:$F$81,MATCH($B40,'Capacidade UAS-CUAS'!$E$4:$E$81,0)),"") | D40: =IFERROR(INDEX('Capacidade UAS-CUAS'!$B$4:$B$81,MATCH($B40,'Capacidade UAS-CUAS'!$E$4:$E$81,0)),"") | E40: =IFERROR(INDEX('Capacidade UAS-CUAS'!$D$4:$D$81,MATCH($B40,'Capacidade UAS-CUAS'!$E$4:$E$81,0)),"")
...

Sheet Análise Serviços
A1: ANÁLISE POR MILITAR — SERVIÇOS REALIZADOS
A2: Atualiza automaticamente a partir do registo à esquerda
A3: NM | B3: Nome | C3: Subunidade | D3: Total | E3: UAS | F3: C-UAS | G3: Reconhec. | H3: Exercício | I3: Apoio Op. | J3: Recolha Img.
A4: ='Capacidade UAS-CUAS'!E4 -> 2140038 | B4: ='Capacidade UAS-CUAS'!F4 -> Luis Manuel Maceiro Cantante | C4: ='Capacidade UAS-CUAS'!B4 -> Comando / SOI | D4: =COUNTIF(Serviços!$B$4:$B$304,A4) -> 0 | E4: =COUNTIFS(Serviços!$B$4:$B$304,A4,Serviços!$F$4:$F$304,"UAS") -> 0 | F4: =COUNTIFS(Serviços!$B$4:$B$304,A4,Serviços!$F$4:$F$304,"C-UAS") -> 0 | G4: =COUNTIFS(Serviços!$B$4:$B$304,A4,Serviços!$H$4:$H$304,"Reconhecimento") -> 0 | H4: =COUNTIFS(Serviços!$B$4:$B$304,A4,Serviços!$H$4:$H$304,"Exercício") -> 0 | I4: =COUNTIFS(Serviços!$B$4:$B$304,A4,Serviços!$H$4:$H$304,"Apoio a Operação") -> 0 | J4: =COUNTIFS(Serviços!$B$4:$B$304,A4,Serviços!$H$4:$H$304,"Recolha de Imagens") -> 0
A5: ='Capacidade UAS-CUAS'!E5 -> 2020825 | B5: ='Capacidade UAS-CUAS'!F5 -> António João Carlos e Granja | C5: ='Capacidade UAS-CUAS'!B5 -> Secretaria GIOP | D5: =COUNTIF(Serviços!$B$4:$B$304,A5) -> 2 | E5: =COUNTIFS(Serviços!$B$4:$B$304,A5,Serviços!$F$4:$F$304,"UAS") -> 1 | F5: =COUNTIFS(Serviços!$B$4:$B$304,A5,Serviços!$F$4:$F$304,"C-UAS") -> 1 | G5: =COUNTIFS(Serviços!$B$4:$B$304,A5,Serviços!$H$4:$H$304,"Reconhecimento") -> 0 | H5: =COUNTIFS(Serviços!$B$4:$B$304,A5,Serviços!$H$4:$H$304,"Exercício") -> 0 | I5: =COUNTIFS(Serviços!$B$4:$B$304,A5,Serviços!$H$4:$H$304,"Apoio a Operação") -> 1 | J5: =COUNTIFS(Serviços!$B$4:$B$304,A5,Serviços!$H$4:$H$304,"Recolha de Imagens") -> 1
A6: ='Capacidade UAS-CUAS'!E6 -> 1970024 | B6: ='Capacidade UAS-CUAS'!F6 -> Manuel António Gonçalves Cordeiro | C6: ='Capacidade UAS-CUAS'!B6 -> SOI | D6: =COUNTIF(Serviços!$B$4:$B$304,A6) -> 2 | E6: =COUNTIFS(Serviços!$B$4:$B$304,A6,Serviços!$F$4:$F$304,"UAS") -> 1 | F6: =COUNTIFS(Serviços!$B$4:$B$304,A6,Serviços!$F$4:$F$304,"C-UAS") -> 1 | G6: =COUNTIFS(Serviços!$B$4:$B$304,A6,Serviços!$H$4:$H$304,"Reconhecimento") -> 0 | H6: =COUNTIFS(Serviços!$B$4:$B$304,A6,Serviços!$H$4:$H$304,"Exercício") -> 2 | I6: =COUNTIFS(Serviços!$B$4:$B$304,A6,Serviços!$H$4:$H$304,"Apoio a Operação") -> 0 | J6: =COUNTIFS(Serviços!$B$4:$B$304,A6,Serviços!$H$4:$H$304,"Recolha de Imagens") -> 0
A7: ='Capacidade UAS-CUAS'!E7 -> 2031108 | B7: ='Capacidade UAS-CUAS'!F7 -> Hélder Simão Nunes | C7: ='Capacidade UAS-CUAS'!B7 -> SOI | D7: =COUNTIF(Serviços!$B$4:$B$304,A7) -> 0 | E7: =COUNTIFS(Serviços!$B$4:$B$304,A7,Serviços!$F$4:$F$304,"UAS") -> 0 | F7: =COUNTIFS(Serviços!$B$4:$B$304,A7,Serviços!$F$4:$F$304,"C-UAS") -> 0 | G7: =COUNTIFS(Serviços!$B$4:$B$304,A7,Serviços!$H$4:$H$304,"Reconhecimento") -> 0 | H7: =COUNTIFS(Serviços!$B$4:$B$304,A7,Serviços!$H$4:$H$304,"Exercício") -> 0 | I7: =COUNTIFS(Serviços!$B$4:$B$304,A7,Serviços!$H$4:$H$304,"Apoio a Operação") -> 0 | J7: =COUNTIFS(Serviços!$B$4:$B$304,A7,Serviços!$H$4:$H$304,"Recolha de Imagens") -> 0
A8: ='Capacidade UAS-CUAS'!E8 -> 2030883 | B8: ='Capacidade UAS-CUAS'!F8 -> Paulo Sérgio Pessanha Saraiva Loureiro | C8: ='Capacidade UAS-CUAS'!B8 -> SOI | D8: =COUNTIF(Serviços!$B$4:$B$304,A8) -> 2 | E8: =COUNTIFS(Serviços!$B$4:$B$304,A8,Serviços!$F$4:$F$304,"UAS") -> 1 | F8: =COUNTIFS(Serviços!$B$4:$B$304,A8,Serviços!$F$4:$F$304,"C-UAS") -> 1 | G8: =COUNTIFS(Serviços!$B$4:$B$304,A8,Serviços!$H$4:$H$304,"Reconhecimento") -> 0 | H8: =COUNTIFS(Serviços!$B$4:$B$304,A8,Serviços!$H$4:$H$304,"Exercício") -> 0 | I8: =COUNTIFS(Serviços!$B$4:$B$304,A8,Serviços!$H$4:$H$304,"Apoio a Operação") -> 1 | J8: =COUNTIFS(Serviços!$B$4:$B$304,A8,Serviços!$H$4:$H$304,"Recolha de Imagens") -> 1
A9: ='Capacidade UAS-CUAS'!E9 -> 2040618 | B9: ='Capacidade UAS-CUAS'!F9 -> Paulo Alexandre Nunes Fernandes Estêvão | C9: ='Capacidade UAS-CUAS'!B9 -> SOI | D9: =COUNTIF(Serviços!$B$4:$B$304,A9) -> 8 | E9: =COUNTIFS(Serviços!$B$4:$B$304,A9,Serviços!$F$4:$F$304,"UAS") -> 5 | F9: =COUNTIFS(Serviços!$B$4:$B$304,A9,Serviços!$F$4:$F$304,"C-UAS") -> 3 | G9: =COUNTIFS(Serviços!$B$4:$B$304,A9,Serviços!$H$4:$H$304,"Reconhecimento") -> 1 | H9: =COUNTIFS(Serviços!$B$4:$B$304,A9,Serviços!$H$4:$H$304,"Exercício") -> 3 | I9: =COUNTIFS(Serviços!$B$4:$B$304,A9,Serviços!$H$4:$H$304,"Apoio a Operação") -> 1 | J9: =COUNTIFS(Serviços!$B$4:$B$304,A9,Serviços!$H$4:$H$304,"Recolha de Imagens") -> 3
A10: ='Capacidade UAS-CUAS'!E10 -> 2090487 | B10: ='Capacidade UAS-CUAS'!F10 -> Wilson da Silva Sousa | C10: ='Capacidade UAS-CUAS'!B10 -> SOI | D10: =COUNTIF(Serviços!$B$4:$B$304,A10) -> 3 | E10: =COUNTIFS(Serviços!$B$4:$B$304,A10,Serviços!$F$4:$F$304,"UAS") -> 1 | F10: =COUNTIFS(Serviços!$B$4:$B$304,A10,Serviços!$F$4:$F$304,"C-UAS") -> 2 | G10: =COUNTIFS(Serviços!$B$4:$B$304,A10,Serviços!$H$4:$H$304,"Reconhecimento") -> 0 | H10: =COUNTIFS(Serviços!$B$4:$B$304,A10,Serviços!$H$4:$H$304,"Exercício") -> 3 | I10: =COUNTIFS(Serviços!$B$4:$B$304,A10,Serviços!$H$4:$H$304,"Apoio a Operação") -> 0 | J10: =COUNTIFS(Serviços!$B$4:$B$304,A10,Serviços!$H$4:$H$304,"Recolha de Imagens") -> 0
A11: ='Capacidade UAS-CUAS'!E11 -> 2030644 | B11: ='Capacidade UAS-CUAS'!F11 -> Bruno Miguel Correia Pimenta | C11: ='Capacidade UAS-CUAS'!B11 -> SOI | D11: =COUNTIF(Serviços!$B$4:$B$304,A11) -> 0 | E11: =COUNTIFS(Serviços!$B$4:$B$304,A11,Serviços!$F$4:$F$304,"UAS") -> 0 | F11: =COUNTIFS(Serviços!$B$4:$B$304,A11,Serviços!$F$4:$F$304,"C-UAS") -> 0 | G11: =COUNTIFS(Serviços!$B$4:$B$304,A11,Serviços!$H$4:$H$304,"Reconhecimento") -> 0 | H11: =COUNTIFS(Serviços!$B$4:$B$304,A11,Serviços!$H$4:$H$304,"Exercício") -> 0 | I11: =COUNTIFS(Serviços!$B$4:$B$304,A11,Serviços!$H$4:$H$304,"Apoio a Operação") -> 0 | J11: =COUNTIFS(Serviços!$B$4:$B$304,A11,Serviços!$H$4:$H$304,"Recolha de Imagens") -> 0
A12: ='Capacidade UAS-CUAS'!E12 -> 2030052 | B12: ='Capacidade UAS-CUAS'!F12 -> Filipe Jorge dos Santos Silva | C12: ='Capacidade UAS-CUAS'!B12 -> SOI | D12: =COUNTIF(Serviços!$B$4:$B$304,A12) -> 2 | E12: =COUNTIFS(Serviços!$B$4:$B$304,A12,Serviços!$F$4:$F$304,"UAS") -> 2 | F12: =COUNTIFS(Serviços!$B$4:$B$304,A12,Serviços!$F$4:$F$304,"C-UAS") -> 0 | G12: =COUNTIFS(Serviços!$B$4:$B$304,A12,Serviços!$H$4:$H$304,"Reconhecimento") -> 2 | H12: =COUNTIFS(Serviços!$B$4:$B$304,A12,Serviços!$H$4:$H$304,"Exercício") -> 0 | I12: =COUNTIFS(Serviços!$B$4:$B$304,A12,Serviços!$H$4:$H$304,"Apoio a Operação") -> 0 | J12: =COUNTIFS(Serviços!$B$4:$B$304,A12,Serviços!$H$4:$H$304,"Recolha de Imagens") -> 0
A13: ='Capacidade UAS-CUAS'!E13 -> 2040185 | B13: ='Capacidade UAS-CUAS'!F13 -> Carlos Manuel Jorge dos Santos | C13: ='Capacidade UAS-CUAS'!B13 -> SOI | D13: =COUNTIF(Serviços!$B$4:$B$304,A13) -> 0 | E13: =COUNTIFS(Serviços!$B$4:$B$304,A13,Serviços!$F$4:$F$304,"UAS") -> 0 | F13: =COUNTIFS(Serviços!$B$4:$B$304,A13,Serviços!$F$4:$F$304,"C-UAS") -> 0 | G13: =COUNTIFS(Serviços!$B$4:$B$304,A13,Serviços!$H$4:$H$304,"Reconhecimento") -> 0 | H13: =COUNTIFS(Serviços!$B$4:$B$304,A13,Serviços!$H$4:$H$304,"Exercício") -> 0 | I13: =COUNTIFS(Serviços!$B$4:$B$304,A13,Serviços!$H$4:$H$304,"Apoio a Operação") -> 0 | J13: =COUNTIFS(Serviços!$B$4:$B$304,A13,Serviços!$H$4:$H$304,"Recolha de Imagens") -> 0
A14: ='Capacidade UAS-CUAS'!E14 -> 2070317 | B14: ='Capacidade UAS-CUAS'!F14 -> José Carlos Soares Gomes | C14: ='Capacidade UAS-CUAS'!B14 -> SOI | D14: =COUNTIF(Serviços!$B$4:$B$304,A14) -> 2 | E14: =COUNTIFS(Serviços!$B$4:$B$304,A14,Serviços!$F$4:$F$304,"UAS") -> 1 | F14: =COUNTIFS(Serviços!$B$4:$B$304,A14,Serviços!$F$4:$F$304,"C-UAS") -> 1 | G14: =COUNTIFS(Serviços!$B$4:$B$304,A14,Serviços!$H$4:$H$304,"Reconhecimento") -> 0 | H14: =COUNTIFS(Serviços!$B$4:$B$304,A14,Serviços!$H$4:$H$304,"Exercício") -> 0 | I14: =COUNTIFS(Serviços!$B$4:$B$304,A14,Serviços!$H$4:$H$304,"Apoio a Operação") -> 1 | J14: =COUNTIFS(Serviços!$B$4:$B$304,A14,Serviços!$H$4:$H$304,"Recolha de Imagens") -> 1
A15: ='Capacidade UAS-CUAS'!E16 -> 2000474 | B15: ='Capacidade UAS-CUAS'!F16 -> Jorge Manuel Graça Rodrigues | C15: ='Capacidade UAS-CUAS'!B16 -> 1.ª Companhia | D15: =COUNTIF(Serviços!$B$4:$B$304,A15) -> 0 | E15: =COUNTIFS(Serviços!$B$4:$B$304,A15,Serviços!$F$4:$F$304,"UAS") -> 0 | F15: =COUNTIFS(Serviços!$B$4:$B$304,A15,Serviços!$F$4:$F$304,"C-UAS") -> 0 | G15: =COUNTIFS(Serviços!$B$4:$B$304,A15,Serviços!$H$4:$H$304,"Reconhecimento") -> 0 | H15: =COUNTIFS(Serviços!$B$4:$B$304,A15,Serviços!$H$4:$H$304,"Exercício") -> 0 | I15: =COUNTIFS(Serviços!$B$4:$B$304,A15,Serviços!$H$4:$H$304,"Apoio a Operação") -> 0 | J15: =COUNTIFS(Serviços!$B$4:$B$304,A15,Serviços!$H$4:$H$304,"Recolha de Imagens") -> 0
A16: ='Capacidade UAS-CUAS'!E17 -> 1970349 | B16: ='Capacidade UAS-CUAS'!F17 -> Paulo Aurélio Fernandes Alves | C16: ='Capacidade UAS-CUAS'!B17 -> 1.ª Companhia | D16: =COUNTIF(Serviços!$B$4:$B$304,A16) -> 0 | E16: =COUNTIFS(Serviços!$B$4:$B$304,A16,Serviços!$F$4:$F$304,"UAS") -> 0 | F16: =COUNTIFS(Serviços!$B$4:$B$304,A16,Serviços!$F$4:$F$304,"C-UAS") -> 0 | G16: =COUNTIFS(Serviços!$B$4:$B$304,A16,Serviços!$H$4:$H$304,"Reconhecimento") -> 0 | H16: =COUNTIFS(Serviços!$B$4:$B$304,A16,Serviços!$H$4:$H$304,"Exercício") -> 0 | I16: =COUNTIFS(Serviços!$B$4:$B$304,A16,Serviços!$H$4:$H$304,"Apoio a Operação") -> 0 | J16: =COUNTIFS(Serviços!$B$4:$B$304,A16,Serviços!$H$4:$H$304,"Recolha de Imagens") -> 0
A17: ='Capacidade UAS-CUAS'!E18 -> 2000796 | B17: ='Capacidade UAS-CUAS'!F18 -> Jorge António Monteiro Silvano | C17: ='Capacidade UAS-CUAS'!B18 -> 1.ª Companhia | D17: =COUNTIF(Serviços!$B$4:$B$304,A17) -> 1 | E17: =COUNTIFS(Serviços!$B$4:$B$304,A17,Serviços!$F$4:$F$304,"UAS") -> 1 | F17: =COUNTIFS(Serviços!$B$4:$B$304,A17,Serviços!$F$4:$F$304,"C-UAS") -> 0 | G17: =COUNTIFS(Serviços!$B$4:$B$304,A17,Serviços!$H$4:$H$304,"Reconhecimento") -> 1 | H17: =COUNTIFS(Serviços!$B$4:$B$304,A17,Serviços!$H$4:$H$304,"Exercício") -> 0 | I17: =COUNTIFS(Serviços!$B$4:$B$304,A17,Serviços!$H$4:$H$304,"Apoio a Operação") -> 0 | J17: =COUNTIFS(Serviços!$B$4:$B$304,A17,Serviços!$H$4:$H$304,"Recolha de Imagens") -> 0
A18: ='Capacidade UAS-CUAS'!E19 -> 2070254 | B18: ='Capacidade UAS-CUAS'!F19 -> Sílvio Manuel Supico Serra | C18: ='Capacidade UAS-CUAS'!B19 -> 1.ª Companhia | D18: =COUNTIF(Serviços!$B$4:$B$304,A18) -> 0 | E18: =COUNTIFS(Serviços!$B$4:$B$304,A18,Serviços!$F$4:$F$304,"UAS") -> 0 | F18: =COUNTIFS(Serviços!$B$4:$B$304,A18,Serviços!$F$4:$F$304,"C-UAS") -> 0 | G18: =COUNTIFS(Serviços!$B$4:$B$304,A18,Serviços!$H$4:$H$304,"Reconhecimento") -> 0 | H18: =COUNTIFS(Serviços!$B$4:$B$304,A18,Serviços!$H$4:$H$304,"Exercício") -> 0 | I18: =COUNTIFS(Serviços!$B$4:$B$304,A18,Serviços!$H$4:$H$304,"Apoio a Operação") -> 0 | J18: =COUNTIFS(Serviços!$B$4:$B$304,A18,Serviços!$H$4:$H$304,"Recolha de Imagens") -> 0
A19: ='Capacidade UAS-CUAS'!E20 -> 2150382 | B19: ='Capacidade UAS-CUAS'!F20 -> Pedro Miguel Rodrigues Carrapatoso | C19: ='Capacidade UAS-CUAS'!B20 -> 1.ª Companhia | D19: =COUNTIF(Serviços!$B$4:$B$304,A19) -> 0 | E19: =COUNTIFS(Serviços!$B$4:$B$304,A19,Serviços!$F$4:$F$304,"UAS") -> 0 | F19: =COUNTIFS(Serviços!$B$4:$B$304,A19,Serviços!$F$4:$F$304,"C-UAS") -> 0 | G19: =COUNTIFS(Serviços!$B$4:$B$304,A19,Serviços!$H$4:$H$304,"Reconhecimento") -> 0 | H19: =COUNTIFS(Serviços!$B$4:$B$304,A19,Serviços!$H$4:$H$304,"Exercício") -> 0 | I19: =COUNTIFS(Serviços!$B$4:$B$304,A19,Serviços!$H$4:$H$304,"Apoio a Operação") -> 0 | J19: =COUNTIFS(Serviços!$B$4:$B$304,A19,Serviços!$H$4:$H$304,"Recolha de Imagens") -> 0
A20: ='Capacidade UAS-CUAS'!E21 -> 2210742 | B20: ='Capacidade UAS-CUAS'!F21 -> Leandro Filipe da Cruz Silva | C20: ='Capacidade UAS-CUAS'!B21 -> 1.ª Companhia | D20: =COUNTIF(Serviços!$B$4:$B$304,A20) -> 0 | E20: =COUNTIFS(Serviços!$B$4:$B$304,A20,Serviços!$F$4:$F$304,"UAS") -> 0 | F20: =COUNTIFS(Serviços!$B$4:$B$304,A20,Serviços!$F$4:$F$304,"C-UAS") -> 0 | G20: =COUNTIFS(Serviços!$B$4:$B$304,A20,Serviços!$H$4:$H$304,"Reconhecimento") -> 0 | H20: =COUNTIFS(Serviços!$B$4:$B$304,A20,Serviços!$H$4:$H$304,"Exercício") -> 0 | I20: =COUNTIFS(Serviços!$B$4:$B$304,A20,Serviços!$H$4:$H$304,"Apoio a Operação") -> 0 | J20: =COUNTIFS(Serviços!$B$4:$B$304,A20,Serviços!$H$4:$H$304,"Recolha de Imagens") -> 0
A21: ='Capacidade UAS-CUAS'!E22 -> 2071127 | B21: ='Capacidade UAS-CUAS'!F22 -> Alexandre Dias Ramalheiro | C21: ='Capacidade UAS-CUAS'!B22 -> 1.ª Companhia | D21: =COUNTIF(Serviços!$B$4:$B$304,A21) -> 0 | E21: =COUNTIFS(Serviços!$B$4:$B$304,A21,Serviços!$F$4:$F$304,"UAS") -> 0 | F21: =COUNTIFS(Serviços!$B$4:$B$304,A21,Serviços!$F$4:$F$304,"C-UAS") -> 0 | G21: =COUNTIFS(Serviços!$B$4:$B$304,A21,Serviços!$H$4:$H$304,"Reconhecimento") -> 0 | H21: =COUNTIFS(Serviços!$B$4:$B$304,A21,Serviços!$H$4:$H$304,"Exercício") -> 0 | I21: =COUNTIFS(Serviços!$B$4:$B$304,A21,Serviços!$H$4:$H$304,"Apoio a Operação") -> 0 | J21: =COUNTIFS(Serviços!$B$4:$B$304,A21,Serviços!$H$4:$H$304,"Recolha de Imagens") -> 0
A22: ='Capacidade UAS-CUAS'!E23 -> 2000318 | B22: ='Capacidade UAS-CUAS'!F23 -> Rui Fernando Oliveira Custódio | C22: ='Capacidade UAS-CUAS'!B23 -> 1.ª Companhia | D22: =COUNTIF(Serviços!$B$4:$B$304,A22) -> 0 | E22: =COUNTIFS(Serviços!$B$4:$B$304,A22,Serviços!$F$4:$F$304,"UAS") -> 0 | F22: =COUNTIFS(Serviços!$B$4:$B$304,A22,Serviços!$F$4:$F$304,"C-UAS") -> 0 | G22: =COUNTIFS(Serviços!$B$4:$B$304,A22,Serviços!$H$4:$H$304,"Reconhecimento") -> 0 | H22: =COUNTIFS(Serviços!$B$4:$B$304,A22,Serviços!$H$4:$H$304,"Exercício") -> 0 | I22: =COUNTIFS(Serviços!$B$4:$B$304,A22,Serviços!$H$4:$H$304,"Apoio a Operação") -> 0 | J22: =COUNTIFS(Serviços!$B$4:$B$304,A22,Serviços!$H$4:$H$304,"Recolha de Imagens") -> 0
A23: ='Capacidade UAS-CUAS'!E24 -> 2030636 | B23: ='Capacidade UAS-CUAS'!F24 -> Francisco João Alves Silvestre | C23: ='Capacidade UAS-CUAS'!B24 -> 1.ª Companhia | D23: =COUNTIF(Serviços!$B$4:$B$304,A23) -> 0 | E23: =COUNTIFS(Serviços!$B$4:$B$304,A23,Serviços!$F$4:$F$304,"UAS") -> 0 | F23: =COUNTIFS(Serviços!$B$4:$B$304,A23,Serviços!$F$4:$F$304,"C-UAS") -> 0 | G23: =COUNTIFS(Serviços!$B$4:$B$304,A23,Serviços!$H$4:$H$304,"Reconhecimento") -> 0 | H23: =COUNTIFS(Serviços!$B$4:$B$304,A23,Serviços!$H$4:$H$304,"Exercício") -> 0 | I23: =COUNTIFS(Serviços!$B$4:$B$304,A23,Serviços!$H$4:$H$304,"Apoio a Operação") -> 0 | J23: =COUNTIFS(Serviços!$B$4:$B$304,A23,Serviços!$H$4:$H$304,"Recolha de Imagens") -> 0
A24: ='Capacidade UAS-CUAS'!E25 -> 2040499 | B24: ='Capacidade UAS-CUAS'!F25 -> Daniel de Almeida Campos Dias | C24: ='Capacidade UAS-CUAS'!B25 -> 1.ª Companhia | D24: =COUNTIF(Serviços!$B$4:$B$304,A24) -> 0 | E24: =COUNTIFS(Serviços!$B$4:$B$304,A24,Serviços!$F$4:$F$304,"UAS") -> 0 | F24: =COUNTIFS(Serviços!$B$4:$B$304,A24,Serviços!$F$4:$F$304,"C-UAS") -> 0 | G24: =COUNTIFS(Serviços!$B$4:$B$304,A24,Serviços!$H$4:$H$304,"Reconhecimento") -> 0 | H24: =COUNTIFS(Serviços!$B$4:$B$304,A24,Serviços!$H$4:$H$304,"Exercício") -> 0 | I24: =COUNTIFS(Serviços!$B$4:$B$304,A24,Serviços!$H$4:$H$304,"Apoio a Operação") -> 0 | J24: =COUNTIFS(Serviços!$B$4:$B$304,A24,Serviços!$H$4:$H$304,"Recolha de Imagens") -> 0
A25: ='Capacidade UAS-CUAS'!E26 -> 2060731 | B25: ='Capacidade UAS-CUAS'!F26 -> André Simões Sabino | C25: ='Capacidade UAS-CUAS'!B26 -> 1.ª Companhia | D25: =COUNTIF(Serviços!$B$4:$B$304,A25) -> 0 | E25: =COUNTIFS(Serviços!$B$4:$B$304,A25,Serviços!$F$4:$F$304,"UAS") -> 0 | F25: =COUNTIFS(Serviços!$B$4:$B$304,A25,Serviços!$F$4:$F$304,"C-UAS") -> 0 | G25: =COUNTIFS(Serviços!$B$4:$B$304,A25,Serviços!$H$4:$H$304,"Reconhecimento") -> 0 | H25: =COUNTIFS(Serviços!$B$4:$B$304,A25,Serviços!$H$4:$H$304,"Exercício") -> 0 | I25: =COUNTIFS(Serviços!$B$4:$B$304,A25,Serviços!$H$4:$H$304,"Apoio a Operação") -> 0 | J25: =COUNTIFS(Serviços!$B$4:$B$304,A25,Serviços!$H$4:$H$304,"Recolha de Imagens") -> 0
A26: ='Capacidade UAS-CUAS'!E27 -> 2071255 | B26: ='Capacidade UAS-CUAS'!F27 -> Marco Paulo Pedro Santos | C26: ='Capacidade UAS-CUAS'!B27 -> 1.ª Companhia | D26: =COUNTIF(Serviços!$B$4:$B$304,A26) -> 0 | E26: =COUNTIFS(Serviços!$B$4:$B$304,A26,Serviços!$F$4:$F$304,"UAS") -> 0 | F26: =COUNTIFS(Serviços!$B$4:$B$304,A26,Serviços!$F$4:$F$304,"C-UAS") -> 0 | G26: =COUNTIFS(Serviços!$B$4:$B$304,A26,Serviços!$H$4:$H$304,"Reconhecimento") -> 0 | H26: =COUNTIFS(Serviços!$B$4:$B$304,A26,Serviços!$H$4:$H$304,"Exercício") -> 0 | I26: =COUNTIFS(Serviços!$B$4:$B$304,A26,Serviços!$H$4:$H$304,"Apoio a Operação") -> 0 | J26: =COUNTIFS(Serviços!$B$4:$B$304,A26,Serviços!$H$4:$H$304,"Recolha de Imagens") -> 0
... A37: ='Capacidade UAS-CUAS'!E38 -> 1990953 | B37: ='Capacidade UAS-CUAS'!F38 -> Orlando Augusto Gil Cosme | C37: ='Capacidade UAS-CUAS'!B38 -> 2.ª Companhia | D37: =COUNTIF(Serviços!$B$4:$B$304,A37) -> 0 | E37: =COUNTIFS(Serviços!$B$4:$B$304,A37,Serviços!$F$4:$F$304,"UAS") -> 0 | F37: =COUNTIFS(Serviços!$B$4:$B$304,A37,Serviços!$F$4:$F$304,"C-UAS") -> 0 | G37: =COUNTIFS(Serviços!$B$4:$B$304,A37,Serviços!$H$4:$H$304,"Reconhecimento") -> 0 | H37: =COUNTIFS(Serviços!$B$4:$B$304,A37,Serviços!$H$4:$H$304,"Exercício") -> 0 | I37: =COUNTIFS(Serviços!$B$4:$B$304,A37,Serviços!$H$4:$H$304,"Apoio a Operação") -> 0 | J37: =COUNTIFS(Serviços!$B$4:$B$304,A37,Serviços!$H$4:$H$304,"Recolha de Imagens") -> 0
A38: ='Capacidade UAS-CUAS'!#REF! -> #REF! | B38: ='Capacidade UAS-CUAS'!#REF! -> #REF! | C38: ='Capacidade UAS-CUAS'!#REF! -> #REF! | D38: =COUNTIF(Serviços!$B$4:$B$304,A38) -> 0 | E38: =COUNTIFS(Serviços!$B$4:$B$304,A38,Serviços!$F$4:$F$304,"UAS") -> 0 | F38: =COUNTIFS(Serviços!$B$4:$B$304,A38,Serviços!$F$4:$F$304,"C-UAS") -> 0 | G38: =COUNTIFS(Serviços!$B$4:$B$304,A38,Serviços!$H$4:$H$304,"Reconhecimento") -> 0 | H38: =COUNTIFS(Serviços!$B$4:$B$304,A38,Serviços!$H$4:$H$304,"Exercício") -> 0 | I38: =COUNTIFS(Serviços!$B$4:$B$304,A38,Serviços!$H$4:$H$304,"Apoio a Operação") -> 0 | J38: =COUNTIFS(Serviços!$B$4:$B$304,A38,Serviços!$H$4:$H$304,"Recolha de Imagens") -> 0
A39: ='Capacidade UAS-CUAS'!E39 -> 2060540 | B39: ='Capacidade UAS-CUAS'!F39 -> Alexandre Filipe Correia Tomázio | C39: ='Capacidade UAS-CUAS'!B39 -> 2.ª Companhia | D39: =COUNTIF(Serviços!$B$4:$B$304,A39) -> 0 | E39: =COUNTIFS(Serviços!$B$4:$B$304,A39,Serviços!$F$4:$F$304,"UAS") -> 0 | F39: =COUNTIFS(Serviços!$B$4:$B$304,A39,Serviços!$F$4:$F$304,"C-UAS") -> 0 | G39: =COUNTIFS(Serviços!$B$4:$B$304,A39,Serviços!$H$4:$H$304,"Reconhecimento") -> 0 | H39: =COUNTIFS(Serviços!$B$4:$B$304,A39,Serviços!$H$4:$H$304,"Exercício") -> 0 | I39: =COUNTIFS(Serviços!$B$4:$B$304,A39,Serviços!$H$4:$H$304,"Apoio a Operação") -> 0 | J39: =COUNTIFS(Serviços!$B$4:$B$304,A39,Serviços!$H$4:$H$304,"Recolha de Imagens") -> 0
A40: ='Capacidade UAS-CUAS'!E41 -> 2150448 | B40: ='Capacidade UAS-CUAS'!F41 -> João Maria Domingos Henriques | C40: ='Capacidade UAS-CUAS'!B41 -> 2.ª Companhia | D40: =COUNTIF(Serviços!$B$4:$B$304,A40) -> 0 | E40: =COUNTIFS(Serviços!$B$4:$B$304,A40,Serviços!$F$4:$F$304,"UAS") -> 0 | F40: =COUNTIFS(Serviços!$B$4:$B$304,A40,Serviços!$F$4:$F$304,"C-UAS") -> 0 | G40: =COUNTIFS(Serviços!$B$4:$B$304,A40,Serviços!$H$4:$H$304,"Reconhecimento") -> 0 | H40: =COUNTIFS(Serviços!$B$4:$B$304,A40,Serviços!$H$4:$H$304,"Exercício") -> 0 | I40: =COUNTIFS(Serviços!$B$4:$B$304,A40,Serviços!$H$4:$H$304,"Apoio a Operação") -> 0 | J40: =COUNTIFS(Serviços!$B$4:$B$304,A40,Serviços!$H$4:$H$304,"Recolha de Imagens") -> 0
A41: ='Capacidade UAS-CUAS'!E42 -> 1991035 | B41: ='Capacidade UAS-CUAS'!F42 -> Bruno Miguel Lameiras Patrocínio | C41: ='Capacidade UAS-CUAS'!B42 -> 2.ª Companhia | D41: =COUNTIF(Serviços!$B$4:$B$304,A41) -> 0 | E41: =COUNTIFS(Serviços!$B$4:$B$304,A41,Serviços!$F$4:$F$304,"UAS") -> 0 | F41: =COUNTIFS(Serviços!$B$4:$B$304,A41,Serviços!$F$4:$F$304,"C-UAS") -> 0 | G41: =COUNTIFS(Serviços!$B$4:$B$304,A41,Serviços!$H$4:$H$304,"Reconhecimento") -> 0 | H41: =COUNTIFS(Serviços!$B$4:$B$304,A41,Serviços!$H$4:$H$304,"Exercício") -> 0 | I41: =COUNTIFS(Serviços!$B$4:$B$304,A41,Serviços!$H$4:$H$304,"Apoio a Operação") -> 0 | J41: =COUNTIFS(Serviços!$B$4:$B$304,A41,Serviços!$H$4:$H$304,"Recolha de Imagens") -> 0
A42: ='Capacidade UAS-CUAS'!E43 -> 2070759 | B42: ='Capacidade UAS-CUAS'!F43 -> David Filipe Monteiro Pereira | C42: ='Capacidade UAS-CUAS'!B43 -> 2.ª Companhia | D42: =COUNTIF(Serviços!$B$4:$B$304,A42) -> 0 | E42: =COUNTIFS(Serviços!$B$4:$B$304,A42,Serviços!$F$4:$F$304,"UAS") -> 0 | F42: =COUNTIFS(Serviços!$B$4:$B$304,A42,Serviços!$F$4:$F$304,"C-UAS") -> 0 | G42: =COUNTIFS(Serviços!$B$4:$B$304,A42,Serviços!$H$4:$H$304,"Reconhecimento") -> 0 | H42: =COUNTIFS(Serviços!$B$4:$B$304,A42,Serviços!$H$4:$H$304,"Exercício") -> 0 | I42: =COUNTIFS(Serviços!$B$4:$B$304,A42,Serviços!$H$4:$H$304,"Apoio a Operação") -> 0 | J42: =COUNTIFS(Serviços!$B$4:$B$304,A42,Serviços!$H$4:$H$304,"Recolha de Imagens") -> 0
A43: ='Capacidade UAS-CUAS'!E44 -> 2070922 | B43: ='Capacidade UAS-CUAS'!F44 -> Nuno Pedro Rolo Correia Veloso | C43: ='Capacidade UAS-CUAS'!B44 -> 2.ª Companhia | D43: =COUNTIF(Serviços!$B$4:$B$304,A43) -> 1 | E43: =COUNTIFS(Serviços!$B$4:$B$304,A43,Serviços!$F$4:$F$304,"UAS") -> 1 | F43: =COUNTIFS(Serviços!$B$4:$B$304,A43,Serviços!$F$4:$F$304,"C-UAS") -> 0 | G43: =COUNTIFS(Serviços!$B$4:$B$304,A43,Serviços!$H$4:$H$304,"Reconhecimento") -> 1 | H43: =COUNTIFS(Serviços!$B$4:$B$304,A43,Serviços!$H$4:$H$304,"Exercício") -> 0 | I43: =COUNTIFS(Serviços!$B$4:$B$304,A43,Serviços!$H$4:$H$304,"Apoio a Operação") -> 0 | J43: =COUNTIFS(Serviços!$B$4:$B$304,A43,Serviços!$H$4:$H$304,"Recolha de Imagens") -> 0
A44: ='Capacidade UAS-CUAS'!E45 -> 2070960 | B44: ='Capacidade UAS-CUAS'!F45 -> Nuno Duarte Beira Pires Pereira | C44: ='Capacidade UAS-CUAS'!B45 -> 2.ª Companhia | D44: =COUNTIF(Serviços!$B$4:$B$304,A44) -> 0 | E44: =COUNTIFS(Serviços!$B$4:$B$304,A44,Serviços!$F$4:$F$304,"UAS") -> 0 | F44: =COUNTIFS(Serviços!$B$4:$B$304,A44,Serviços!$F$4:$F$304,"C-UAS") -> 0 | G44: =COUNTIFS(Serviços!$B$4:$B$304,A44,Serviços!$H$4:$H$304,"Reconhecimento") -> 0 | H44: =COUNTIFS(Serviços!$B$4:$B$304,A44,Serviços!$H$4:$H$304,"Exercício") -> 0 | I44: =COUNTIFS(Serviços!$B$4:$B$304,A44,Serviços!$H$4:$H$304,"Apoio a Operação") -> 0 | J44: =COUNTIFS(Serviços!$B$4:$B$304,A44,Serviços!$H$4:$H$304,"Recolha de Imagens") -> 0
A45: ='Capacidade UAS-CUAS'!E46 -> 2120476 | B45: ='Capacidade UAS-CUAS'!F46 -> Tiago Realinho da Costa | C45: ='Capacidade UAS-CUAS'!B46 -> 2.ª Companhia | D45: =COUNTIF(Serviços!$B$4:$B$304,A45) -> 0 | E45: =COUNTIFS(Serviços!$B$4:$B$304,A45,Serviços!$F$4:$F$304,"UAS") -> 0 | F45: =COUNTIFS(Serviços!$B$4:$B$304,A45,Serviços!$F$4:$F$304,"C-UAS") -> 0 | G45: =COUNTIFS(Serviços!$B$4:$B$304,A45,Serviços!$H$4:$H$304,"Reconhecimento") -> 0 | H45: =COUNTIFS(Serviços!$B$4:$B$304,A45,Serviços!$H$4:$H$304,"Exercício") -> 0 | I45: =COUNTIFS(Serviços!$B$4:$B$304,A45,Serviços!$H$4:$H$304,"Apoio a Operação") -> 0 | J45: =COUNTIFS(Serviços!$B$4:$B$304,A45,Serviços!$H$4:$H$304,"Recolha de Imagens") -> 0
A46: ='Capacidade UAS-CUAS'!E47 -> 2220821 | B46: ='Capacidade UAS-CUAS'!F47 -> João Carlos Pereira Nunes | C46: ='Capacidade UAS-CUAS'!B47 -> 2.ª Companhia | D46: =COUNTIF(Serviços!$B$4:$B$304,A46) -> 0 | E46: =COUNTIFS(Serviços!$B$4:$B$304,A46,Serviços!$F$4:$F$304,"UAS") -> 0 | F46: =COUNTIFS(Serviços!$B$4:$B$304,A46,Serviços!$F$4:$F$304,"C-UAS") -> 0 | G46: =COUNTIFS(Serviços!$B$4:$B$304,A46,Serviços!$H$4:$H$304,"Reconhecimento") -> 0 | H46: =COUNTIFS(Serviços!$B$4:$B$304,A46,Serviços!$H$4:$H$304,"Exercício") -> 0 | I46: =COUNTIFS(Serviços!$B$4:$B$304,A46,Serviços!$H$4:$H$304,"Apoio a Operação") -> 0 | J46: =COUNTIFS(Serviços!$B$4:$B$304,A46,Serviços!$H$4:$H$304,"Recolha de Imagens") -> 0
A47: ='Capacidade UAS-CUAS'!E48 -> 2090305 | B47: ='Capacidade UAS-CUAS'!F48 -> Fabio Emanuel Marques Antunes | C47: ='Capacidade UAS-CUAS'!B48 -> 2.ª Companhia | D47: =COUNTIF(Serviços!$B$4:$B$304,A47) -> 0 | E47: =COUNTIFS(Serviços!$B$4:$B$304,A47,Serviços!$F$4:$F$304,"UAS") -> 0 | F47: =COUNTIFS(Serviços!$B$4:$B$304,A47,Serviços!$F$4:$F$304,"C-UAS") -> 0 | G47: =COUNTIFS(Serviços!$B$4:$B$304,A47,Serviços!$H$4:$H$304,"Reconhecimento") -> 0 | H47: =COUNTIFS(Serviços!$B$4:$B$304,A47,Serviços!$H$4:$H$304,"Exercício") -> 0 | I47: =COUNTIFS(Serviços!$B$4:$B$304,A47,Serviços!$H$4:$H$304,"Apoio a Operação") -> 0 | J47: =COUNTIFS(Serviços!$B$4:$B$304,A47,Serviços!$H$4:$H$304,"Recolha de Imagens") -> 0
A48: ='Capacidade UAS-CUAS'!E49 -> 1970446 | B48: ='Capacidade UAS-CUAS'!F49 -> Paulo Jorge dos Santos Coelho | C48: ='Capacidade UAS-CUAS'!B49 -> 2.ª Companhia | D48: =COUNTIF(Serviços!$B$4:$B$304,A48) -> 0 | E48: =COUNTIFS(Serviços!$B$4:$B$304,A48,Serviços!$F$4:$F$304,"UAS") -> 0 | F48: =COUNTIFS(Serviços!$B$4:$B$304,A48,Serviços!$F$4:$F$304,"C-UAS") -> 0 | G48: =COUNTIFS(Serviços!$B$4:$B$304,A48,Serviços!$H$4:$H$304,"Reconhecimento") -> 0 | H48: =COUNTIFS(Serviços!$B$4:$B$304,A48,Serviços!$H$4:$H$304,"Exercício") -> 0 | I48: =COUNTIFS(Serviços!$B$4:$B$304,A48,Serviços!$H$4:$H$304,"Apoio a Operação") -> 0 | J48: =COUNTIFS(Serviços!$B$4:$B$304,A48,Serviços!$H$4:$H$304,"Recolha de Imagens") -> 0
A49: ='Capacidade UAS-CUAS'!E50 -> 1990783 | B49: ='Capacidade UAS-CUAS'!F50 -> Luís Filipe Sequeira Batista Pombo | C49: ='Capacidade UAS-CUAS'!B50 -> 2.ª Companhia | D49: =COUNTIF(Serviços!$B$4:$B$304,A49) -> 0 | E49: =COUNTIFS(Serviços!$B$4:$B$304,A49,Serviços!$F$4:$F$304,"UAS") -> 0 | F49: =COUNTIFS(Serviços!$B$4:$B$304,A49,Serviços!$F$4:$F$304,"C-UAS") -> 0 | G49: =COUNTIFS(Serviços!$B$4:$B$304,A49,Serviços!$H$4:$H$304,"Reconhecimento") -> 0 | H49: =COUNTIFS(Serviços!$B$4:$B$304,A49,Serviços!$H$4:$H$304,"Exercício") -> 0 | I49: =COUNTIFS(Serviços!$B$4:$B$304,A49,Serviços!$H$4:$H$304,"Apoio a Operação") -> 0 | J49: =COUNTIFS(Serviços!$B$4:$B$304,A49,Serviços!$H$4:$H$304,"Recolha de Imagens") -> 0
A50: ='Capacidade UAS-CUAS'!E51 -> 2010584 | B50: ='Capacidade UAS-CUAS'!F51 -> Alberto Pinto de Andrade | C50: ='Capacidade UAS-CUAS'!B51 -> 2.ª Companhia | D50: =COUNTIF(Serviços!$B$4:$B$304,A50) -> 0 | E50: =COUNTIFS(Serviços!$B$4:$B$304,A50,Serviços!$F$4:$F$304,"UAS") -> 0 | F50: =COUNTIFS(Serviços!$B$4:$B$304,A50,Serviços!$F$4:$F$304,"C-UAS") -> 0 | G50: =COUNTIFS(Serviços!$B$4:$B$304,A50,Serviços!$H$4:$H$304,"Reconhecimento") -> 0 | H50: =COUNTIFS(Serviços!$B$4:$B$304,A50,Serviços!$H$4:$H$304,"Exercício") -> 0 | I50: =COUNTIFS(Serviços!$B$4:$B$304,A50,Serviços!$H$4:$H$304,"Apoio a Operação") -> 0 | J50: =COUNTIFS(Serviços!$B$4:$B$304,A50,Serviços!$H$4:$H$304,"Recolha de Imagens") -> 0
...

Sheet Nomeação UAS-CUAS
A1: GRUPO DE INTERVENÇÃO DE ORDEM PÚBLICA — NOMEAÇÃO AUTOMÁTICA UAS / C-UAS
A2: Introduza a data pretendida na célula azul (B4). A lista é gerada automaticamente: primeiro os militares disponíveis, depois os indisponíveis (a vermelho), cruzando a escala de pelotões com os serviços já marcados.
A3: Data da nomeação: | B3: 46262 | C3: clicar duas vez e escolher no calendário data pretendida(não escrever data) | E3: Disponíveis: | F3: =COUNTIF($T$8:$T$83,TRUE()) -> 19 | G3: Indisponíveis: | H3: =COUNTIF($T$8:$T$83,FALSE()) -> 57
A6: Disponível | B6: Indisponível (folga/PV/CAR/serviço fora/serviço já marcado)
A7: NM | B7: Nome completo | C7: Posto | D7: Subunidade | E7: Pelotão | F7: Situação do dia | G7: Disponível | H7: Motivo | K7: NM | L7: Nome completo | M7: Posto | N7: Subunidade | O7: Pelotão | P7: PelotaoKey | Q7: CodigoDia | R7: CodigoDisponivel | S7: ServicoJaMarcado | T7: Disponivel | U7: GroupKey | V7: RowNum | W7: SortRank | X7: Motivo | Y7: CodeNumber
A8: =INDEX($K$8:$K$4133,MATCH(ROW()-7,$W$8:$W$4133,0)) -> 2020825 | B8: =INDEX($L$8:$L$4133,MATCH(ROW()-7,$W$8:$W$4133,0)) -> António João Carlos e Granja | C8: =INDEX($M$8:$M$4133,MATCH(ROW()-7,$W$8:$W$4133,0)) -> Cabo | D8: =INDEX($N$8:$N$4133,MATCH(ROW()-7,$W$8:$W$4133,0)) -> Secretaria GIOP | E8: =INDEX($O$8:$O$4133,MATCH(ROW()-7,$W$8:$W$4133,0)) -> — | F8: =INDEX($Q$8:$Q$4133,MATCH(ROW()-7,$W$8:$W$4133,0)) | G8: =IF(INDEX($T$8:$T$4133,MATCH(ROW()-7,$W$8:$W$4133,0)),"SIM","NÃO") -> SIM | H8: =INDEX($X$8:$X$4133,MATCH(ROW()-7,$W$8:$W$4133,0)) -> Não pertence a companhia operacional — disponível por defeito | K8: ='[1]Capacidade UAS-CUAS'!E4 -> 2140038 | L8: ='[1]Capacidade UAS-CUAS'!F4 -> Luis Manuel Maceiro Cantante | M8: ='[1]Capacidade UAS-CUAS'!D4 -> Tenente | N8: ='[1]Capacidade UAS-CUAS'!B4 -> Comando / SOI | O8: ='[1]Capacidade UAS-CUAS'!C4 -> — | P8: =IF(O8="—","",LEFT(O8,FIND(".",O8)-1)&"º") | Q8: =IF(P8="","",IFERROR(INDEX(EscalaPelotoes!$B$3:$N$4481,MATCH($B$3,EscalaPelotoes!$A$3:$A$4481,0),MATCH(P8,EscalaPelotoes!$B$2:$N$2,0)),"")) | R8: =IF(O8="—",TRUE(),IF(Q8="",FALSE(),AND(LEFT(Q8,1)="P",ISNUMBER(VALUE(MID(Q8,2,LEN(Q8)-1)))))) -> TRUE | S8: =IF(O8="—",FALSE(),SUMPRODUCT(--(TEXT([1]Serviços!$B$4:$B$400,"0")=TEXT(K8,"0")),--([1]Serviços!$A$4:$A$400=$B$3))>0) -> FALSE | T8: =IF(O8="—",TRUE(),AND(R8,NOT(S8))) -> TRUE | U8: =IF(O8="—",0,IF(T8,1,2)) -> 0 | V8: =ROW() -> 8 | W8: =COUNTIFS($U$8:$U$83,"<"&U8)+COUNTIFS($U$8:$U$83,U8,$Y$8:$Y$83,">"&Y8)+COUNTIFS($U$8:$U$83,U8,$Y$8:$Y$83,Y8,$L$8:$L$83,"<"&L8)+COUNTIFS($U$8:$U$83,U8,$Y$8:$Y$83,Y8,$L$8:$L$83,L8,$V$8:$V$83,"<"&V8)+1 -> 7 | X8: =IF(O8="—","Não pertence a companhia operacional — disponível por defeito",IF(Q8="","Sem dados de escala para esta data",IF(S8,"Já tem serviço UAS/C-UAS marcado neste dia",IF(T8,"Escala do pelotão: "&Q8&" (disponível)","Escala do pelotão: "&Q8&" (indisponível)")))) -> Não pertence a companhia operacional — disponível por defeito | Y8: =IF(O8="—",0,IFERROR(VALUE(MID(Q8,2,1)),0)) -> 0
